Workbook

Sheet ACTIVA
A1: VDO
A2: BALANS NA WINSTVERDELING
A4: ACTIVA | B4: Jaar 1 | D4: Jaar 2 | F4: Jaar 3 | I4: Mutaties
C5: % | E5: % | G5: % | I5: jaar 1 -> 2 | J5: jaar 2 -> 3
A6: Oprichtingskosten | C6: =B6/B$44*100 -> 0 | E6: =D6/D$44*100 -> 0 | G6: =F6/F$44*100 -> 0
A8: VASTE ACTIVA | B8: =B10+B15+B24 -> 304000 | C8: =B8/B$44*100 -> 64.158071 | D8: =D10+D15+D24 -> 262000 | E8: =D8/D$44*100 -> 52.670728 | F8: =F10+F15+F24 -> 220000 | G8: =F8/F$44*100 -> 41.369223 | I8: =D8-B8 -> -42000 | J8: =F8-D8 -> -42000
A10: Immateriële Vaste Activa | B10: =B12+B13 -> 0 | C10: =B10/B$44*100 -> 0 | D10: =D12+D13 -> 0 | E10: =D10/D$44*100 -> 0 | F10: =F12+F13 -> 0 | G10: =F10/F$44*100 -> 0
A12: Octrooien, concessies, … | C12: =B12/B$44*100 -> 0 | E12: =D12/D$44*100 -> 0 | G12: =F12/F$44*100 -> 0 | I12: =D12-B12 -> 0 | J12: =F12-D12 -> 0
A13: Goodwill | C13: =B13/B$44*100 -> 0 | E13: =D13/D$44*100 -> 0 | G13: =F13/F$44*100 -> 0 | I13: =D13-B13 -> 0 | J13: =F13-D13 -> 0
A15: Materiële Vaste Activa | B15: =SUM(B17:B22) -> 304000 | C15: =B15/B$44*100 -> 64.158071 | D15: =SUM(D17:D22) -> 262000 | E15: =D15/D$44*100 -> 52.670728 | F15: =SUM(F17:F22) -> 220000 | G15: =F15/F$44*100 -> 41.369223 | I15: =D15-B15 -> -42000 | J15: =F15-D15 -> -42000
A17: Terrein en gebouwen | B17: ='INVEST TABEL'!C7-'INVEST TABEL'!E7 -> 0 | C17: =B17/B$44*100 -> 0 | D17: =B17-'INVEST TABEL'!F7 -> 0 | E17: =D17/D$44*100 -> 0 | F17: ='INVEST TABEL'!J7 -> 0 | G17: =F17/F$44*100 -> 0 | I17: =D17-B17 -> 0 | J17: =F17-D17 -> 0
A18: Machines, Installaties, Uitrusting | B18: ='INVEST TABEL'!C11-'INVEST TABEL'!E11 -> 270000 | C18: =B18/B$44*100 -> 56.982497 | D18: =B18-'INVEST TABEL'!F11 -> 240000 | E18: =C18-'INVEST TABEL'!G11 -> -29943.018 | F18: =D18-'INVEST TABEL'!G11 -> 210000 | G18: =F18/F$44*100 -> 39.488804 | I18: =D18-B18 -> -30000 | J18: =F18-D18 -> -30000
A19: Meubilair, Inrichting | B19: ='INVEST TABEL'!C16-'INVEST TABEL'!E16 -> 34000 | C19: =B19/B$44*100 -> 7.1755737 | D19: =B19-'INVEST TABEL'!F16 -> 22000 | E19: =C19-'INVEST TABEL'!G16 -> -11992.824 | F19: =D19-'INVEST TABEL'!G16 -> 10000 | G19: =F19/F$44*100 -> 1.8804192 | I19: =D19-B19 -> -12000 | J19: =F19-D19 -> -12000
A20: Rollend Materieel | B20: ='INVEST TABEL'!C20-'INVEST TABEL'!E20 -> 0 | C20: =B20/B$44*100 -> 0 | D20: =B20-'INVEST TABEL'!F20 -> 0 | E20: =D20/D$44*100 -> 0 | F20: ='INVEST TABEL'!J20 -> 0 | G20: =F20/F$44*100 -> 0 | I20: =D20-B20 -> 0 | J20: =F20-D20 -> 0
A21: Leasing en soortgelijke rechten | B21: ='INVEST TABEL'!C24-'INVEST TABEL'!E24 -> 0 | C21: =B21/B$44*100 -> 0 | D21: =B21-'INVEST TABEL'!F24 -> 0 | E21: =D21/D$44*100 -> 0 | F21: ='INVEST TABEL'!J24 -> 0 | G21: =F21/F$44*100 -> 0 | I21: =D21-B21 -> 0 | J21: =F21-D21 -> 0
A22: Overige Materiële Vaste Activa | B22: ='INVEST TABEL'!C29-'INVEST TABEL'!E29 -> 0 | C22: =B22/B$44*100 -> 0 | D22: =B22-'INVEST TABEL'!F29 -> 0 | E22: =D22/D$44*100 -> 0 | F22: ='INVEST TABEL'!J29 -> 0 | G22: =F22/F$44*100 -> 0 | I22: =D22-B22 -> 0 | J22: =F22-D22 -> 0
A24: Financiële Vaste Activa | C24: =B24/B$44*100 -> 0 | E24: =D24/D$44*100 -> 0 | G24: =F24/F$44*100 -> 0 | I24: =D24-B24 -> 0 | J24: =F24-D24 -> 0
A26: VLOTTENDE ACTIVA | B26: =B28+B30+B39+B34+B42 -> 169829.71 | C26: =B26/B$44*100 -> 35.841929 | D26: =D28+D30+D39+D34+D42 -> 235429.99 | E26: =D26/D$44*100 -> 47.329272 | F26: =F28+F30+F39+F34+F42 -> 311796.31 | G26: =F26/F$44*100 -> 58.630777 | I26: =D26-B26 -> 65600.284 | J26: =F26-D26 -> 76366.314
A28: Vorderingen op + 1 Jaar | C28: =B28/B$44*100 -> 0 | E28: =D28/D$44*100 -> 0 | G28: =F28/F$44*100 -> 0 | I28: =D28-B28 -> 0 | J28: =F28-D28 -> 0
A30: Voorraden | B30: =B31+B32 -> 0 | C30: =B30/B$44*100 -> 0 | D30: =D31+D32 -> 0 | E30: =D30/D$44*100 -> 0 | F30: =F31+F32 -> 0 | G30: =F30/F$44*100 -> 0 | I30: =D30-B30 -> 0 | J30: =F30-D30 -> 0
A31: Voorraad Handelsgoederen | C31: =B31/B$44*100 -> 0 | D31: =B31 -> 0 | E31: =D31/D$44*100 -> 0 | F31: =D31 -> 0 | G31: =F31/F$44*100 -> 0 | I31: =D31-B31 -> 0 | J31: =F31-D31 -> 0
A32: Bestellingen in uitvoering | C32: =B32/B$44*100 -> 0 | E32: =D32/D$44*100 -> 0 | G32: =F32/F$44*100 -> 0 | I32: =D32-B32 -> 0 | J32: =F32-D32 -> 0
A34: Vorderingen op - 1 Jaar | B34: =B35+B37+B36 -> 62000 | C34: =B34/B$44*100 -> 13.08487 | D34: =D35+D37+D36 -> 65100 | E34: =D34/D$44*100 -> 13.087269 | F34: =F35+F37+F36 -> 68355 | G34: =F34/F$44*100 -> 12.853606 | I34: =D34-B34 -> 3100 | J34: =F34-D34 -> 3255
A35: Handelsvorderingen | B35: ='70-40-44-55'!C12 -> 62000 | C35: =B35/B$44*100 -> 13.08487 | D35: ='70-40-44-55'!C16 -> 65100 | E35: =D35/D$44*100 -> 13.087269 | F35: ='70-40-44-55'!C20 -> 68355 | G35: =F35/F$44*100 -> 12.853606 | I35: =D35-B35 -> 3100 | J35: =F35-D35 -> 3255
A36: Overige Vorderingen
A37: BTW | B37: =RESULTAAT!K46-RESULTAAT!L59 -> 0 | C37: =B37/B$44*100 -> 0 | D37: =RESULTAAT!M46-RESULTAAT!N59 -> 0 | E37: =D37/D$44*100 -> 0 | F37: =RESULTAAT!O46-RESULTAAT!P59 -> 0 | G37: =F37/F$44*100 -> 0 | I37: =D37-B37 -> 0 | J37: =F37-D37 -> 0
A39: Liquide Middelen | B39: =B40 -> 107829.71 | C39: =B39/B$44*100 -> 22.75706 | D39: =D40 -> 170329.99 | E39: =D39/D$44*100 -> 34.242003 | F39: =F40 -> 243441.31 | G39: =F39/F$44*100 -> 45.777171 | I39: =D39-B39 -> 62500.284 | J39: =F39-D39 -> 73111.314
A40: Bank | B40: ='FIN ANALYSE'!B94 -> 107829.71 | C40: =B40/B$44*100 -> 22.75706 | D40: ='FIN ANALYSE'!C94 -> 170329.99 | E40: =D40/D$44*100 -> 34.242003 | F40: ='FIN ANALYSE'!D94 -> 243441.31 | G40: =F40/F$44*100 -> 45.777171 | I40: =D40-B40 -> 62500.284 | J40: =F40-D40 -> 73111.314
A42: Overlopende rekeningen | C42: =B42/B$44*100 -> 0 | E42: =D42/D$44*100 -> 0 | G42: =F42/F$44*100 -> 0 | I42: =D42-B42 -> 0 | J42: =F42-D42 -> 0
A44: TOTAAL ACTIVA | B44: =B26+B8+B6 -> 473829.71 | C44: 100 | D44: =D26+D8+D6 -> 497429.99 | E44: 100 | F44: =F26+F8+F6 -> 531796.31 | G44: 100 | I44: =D44-B44 -> 23600.284 | J44: =F44-D44 -> 34366.314
B46: =B44-PASSIVA!B58 -> 0 | D46: =D44-PASSIVA!D58 -> 0 | F46: =F44-PASSIVA!F58 -> 0

Sheet ACTIVA analyse
A1: =ACTIVA!A1 -> VDO
A2: =ACTIVA!A2 -> BALANS NA WINSTVERDELING
C3: VERTIKALE ANALYSE | I3: HORIZONTALE ANALYSE
A4: ACTIVA | B4: Jaar 1 | C4: =ACTIVA!B4 -> Jaar 1 | D4: Jaar 2 | E4: =ACTIVA!D4 -> Jaar 2 | F4: Jaar 3 | G4: =ACTIVA!F4 -> Jaar 3 | I4: Mutaties in % | K4: Mutaties
C5: % | E5: % | G5: % | I5: jaar 1 -> 2 | J5: jaar 2 -> 3 | K5: jaar 1 -> 2 | L5: jaar 2 -> 3
A6: =ACTIVA!A6 -> Oprichtingskosten | B6: =ACTIVA!B6 -> 0 | C6: =B6/B$44*100 -> 0 | E6: =D6/D$44*100 -> 0 | G6: =F6/F$44*100 -> 0 | I6: =(D6-B6)/B6*100 -> #DIV/0! | J6: =(F6-D6)/D6*100 -> #DIV/0! | K6: =D6-B6 -> 0 | L6: =F6-D6 -> 0
A8: VASTE ACTIVA | B8: =B10+B15+B24 -> 304000 | C8: =B8/B$44*100 -> 64.158071 | D8: =D10+D15+D24 -> 262000 | E8: =D8/D$44*100 -> 52.670728 | F8: =F10+F15+F24 -> 220000 | G8: =F8/F$44*100 -> 41.369223 | I8: =(D8-B8)/B8*100 -> -13.815789 | J8: =(F8-D8)/D8*100 -> -16.030534 | K8: =D8-B8 -> -42000 | L8: =F8-D8 -> -42000
A10: Immateriële Vaste Activa | B10: =B12+B13 -> 0 | C10: =B10/B$44*100 -> 0 | D10: =D12+D13 -> 0 | E10: =D10/D$44*100 -> 0 | F10: =F12+F13 -> 0 | G10: =F10/F$44*100 -> 0 | I10: =(D10-B10)/B10*100 -> #DIV/0! | J10: =(F10-D10)/D10*100 -> #DIV/0! | K10: =D10-B10 -> 0 | L10: =F10-D10 -> 0
A12: =ACTIVA!A12 -> Octrooien, concessies, … | B12: =ACTIVA!B12 -> 0 | C12: =B12/B$44*100 -> 0 | D12: =ACTIVA!D12 -> 0 | E12: =D12/D$44*100 -> 0 | F12: =ACTIVA!F12 -> 0 | G12: =F12/F$44*100 -> 0 | I12: =(D12-B12)/B12*100 -> #DIV/0! | J12: =(F12-D12)/D12*100 -> #DIV/0! | K12: =D12-B12 -> 0 | L12: =F12-D12 -> 0
A13: =ACTIVA!A13 -> Goodwill | B13: =ACTIVA!B13 -> 0 | C13: =B13/B$44*100 -> 0 | D13: =ACTIVA!D13 -> 0 | E13: =D13/D$44*100 -> 0 | F13: =ACTIVA!F13 -> 0 | G13: =F13/F$44*100 -> 0 | I13: =(D13-B13)/B13*100 -> #DIV/0! | J13: =(F13-D13)/D13*100 -> #DIV/0! | K13: =D13-B13 -> 0 | L13: =F13-D13 -> 0
A15: Materiële Vaste Activa | B15: =SUM(B17:B22) -> 304000 | C15: =B15/B$44*100 -> 64.158071 | D15: =SUM(D17:D22) -> 262000 | E15: =D15/D$44*100 -> 52.670728 | F15: =SUM(F17:F22) -> 220000 | G15: =F15/F$44*100 -> 41.369223 | I15: =(D15-B15)/B15*100 -> -13.815789 | J15: =(F15-D15)/D15*100 -> -16.030534 | K15: =D15-B15 -> -42000 | L15: =F15-D15 -> -42000
A17: =ACTIVA!A17 -> Terrein en gebouwen | B17: =ACTIVA!B17 -> 0 | C17: =B17/B$44*100 -> 0 | D17: =ACTIVA!D17 -> 0 | E17: =D17/D$44*100 -> 0 | F17: =ACTIVA!F17 -> 0 | G17: =F17/F$44*100 -> 0 | I17: =(D17-B17)/B17*100 -> #DIV/0! | J17: =(F17-D17)/D17*100 -> #DIV/0! | K17: =D17-B17 -> 0 | L17: =F17-D17 -> 0
A18: =ACTIVA!A18 -> Machines, Installaties, Uitrusting | B18: =ACTIVA!B18 -> 270000 | C18: =B18/B$44*100 -> 56.982497 | D18: =ACTIVA!D18 -> 240000 | E18: =D18/D$44*100 -> 48.247995 | F18: =ACTIVA!F18 -> 210000 | G18: =F18/F$44*100 -> 39.488804 | I18: =(D18-B18)/B18*100 -> -11.111111 | J18: =(F18-D18)/D18*100 -> -12.5 | K18: =D18-B18 -> -30000 | L18: =F18-D18 -> -30000
A19: =ACTIVA!A19 -> Meubilair, Inrichting | B19: =ACTIVA!B19 -> 34000 | C19: =B19/B$44*100 -> 7.1755737 | D19: =ACTIVA!D19 -> 22000 | E19: =D19/D$44*100 -> 4.4227329 | F19: =ACTIVA!F19 -> 10000 | G19: =F19/F$44*100 -> 1.8804192 | I19: =(D19-B19)/B19*100 -> -35.294118 | J19: =(F19-D19)/D19*100 -> -54.545455 | K19: =D19-B19 -> -12000 | L19: =F19-D19 -> -12000
A20: =ACTIVA!A20 -> Rollend Materieel | B20: =ACTIVA!B20 -> 0 | C20: =B20/B$44*100 -> 0 | D20: =ACTIVA!D20 -> 0 | E20: =D20/D$44*100 -> 0 | F20: =ACTIVA!F20 -> 0 | G20: =F20/F$44*100 -> 0 | I20: =(D20-B20)/B20*100 -> #DIV/0! | J20: =(F20-D20)/D20*100 -> #DIV/0! | K20: =D20-B20 -> 0 | L20: =F20-D20 -> 0
A21: =ACTIVA!A21 -> Leasing en soortgelijke rechten | B21: =ACTIVA!B21 -> 0 | C21: =B21/B$44*100 -> 0 | D21: =ACTIVA!D21 -> 0 | E21: =D21/D$44*100 -> 0 | F21: =ACTIVA!F21 -> 0 | G21: =F21/F$44*100 -> 0 | I21: =(D21-B21)/B21*100 -> #DIV/0! | J21: =(F21-D21)/D21*100 -> #DIV/0! | K21: =D21-B21 -> 0 | L21: =F21-D21 -> 0
A22: =ACTIVA!A22 -> Overige Materiële Vaste Activa | B22: =ACTIVA!B22 -> 0 | C22: =B22/B$44*100 -> 0 | D22: =ACTIVA!D22 -> 0 | E22: =D22/D$44*100 -> 0 | F22: =ACTIVA!F22 -> 0 | G22: =F22/F$44*100 -> 0 | I22: =(D22-B22)/B22*100 -> #DIV/0! | J22: =(F22-D22)/D22*100 -> #DIV/0! | K22: =D22-B22 -> 0 | L22: =F22-D22 -> 0
A24: =ACTIVA!A24 -> Financiële Vaste Activa | B24: =ACTIVA!B24 -> 0 | C24: =B24/B$44*100 -> 0 | D24: =ACTIVA!D24 -> 0 | E24: =D24/D$44*100 -> 0 | F24: =ACTIVA!F24 -> 0 | G24: =F24/F$44*100 -> 0 | I24: =(D24-B24)/B24*100 -> #DIV/0! | J24: =(F24-D24)/D24*100 -> #DIV/0! | K24: =D24-B24 -> 0 | L24: =F24-D24 -> 0
A26: VLOTTENDE ACTIVA | B26: =B28+B30+B39+B34+B42 -> 169829.71 | C26: =B26/B$44*100 -> 35.841929 | D26: =D28+D30+D39+D34+D42 -> 235429.99 | E26: =D26/D$44*100 -> 47.329272 | F26: =F28+F30+F39+F34+F42 -> 311796.31 | G26: =F26/F$44*100 -> 58.630777 | I26: =(D26-B26)/B26*100 -> 38.627095 | J26: =(F26-D26)/D26*100 -> 32.436952 | K26: =D26-B26 -> 65600.284 | L26: =F26-D26 -> 76366.314
A28: =ACTIVA!A28 -> Vorderingen op + 1 Jaar | C28: =B28/B$44*100 -> 0 | E28: =D28/D$44*100 -> 0 | G28: =F28/F$44*100 -> 0 | I28: =(D28-B28)/B28*100 -> #DIV/0! | J28: =(F28-D28)/D28*100 -> #DIV/0! | K28: =D28-B28 -> 0 | L28: =F28-D28 -> 0
A30: =ACTIVA!A30 -> Voorraden | B30: =B31+B32 -> 0 | C30: =B30/B$44*100 -> 0 | D30: =D31+D32 -> 0 | E30: =D30/D$44*100 -> 0 | F30: =F31+F32 -> 0 | G30: =F30/F$44*100 -> 0 | I30: =(D30-B30)/B30*100 -> #DIV/0! | J30: =(F30-D30)/D30*100 -> #DIV/0! | K30: =D30-B30 -> 0 | L30: =F30-D30 -> 0
A31: =ACTIVA!A31 -> Voorraad Handelsgoederen | B31: =ACTIVA!B31 -> 0 | C31: =B31/B$44*100 -> 0 | D31: =ACTIVA!D31 -> 0 | E31: =D31/D$44*100 -> 0 | F31: =ACTIVA!F31 -> 0 | G31: =F31/F$44*100 -> 0 | I31: =(D31-B31)/B31*100 -> #DIV/0! | J31: =(F31-D31)/D31*100 -> #DIV/0! | K31: =D31-B31 -> 0 | L31: =F31-D31 -> 0
A32: =ACTIVA!A32 -> Bestellingen in uitvoering | B32: =ACTIVA!B32 -> 0 | C32: =B32/B$44*100 -> 0 | D32: =ACTIVA!D32 -> 0 | E32: =D32/D$44*100 -> 0 | F32: =ACTIVA!F32 -> 0 | G32: =F32/F$44*100 -> 0 | I32: =(D32-B32)/B32*100 -> #DIV/0! | J32: =(F32-D32)/D32*100 -> #DIV/0! | K32: =D32-B32 -> 0 | L32: =F32-D32 -> 0
A34: =ACTIVA!A34 -> Vorderingen op - 1 Jaar | B34: =B35+B37 -> 62000 | C34: =B34/B$44*100 -> 13.08487 | D34: =D35+D37 -> 65100 | E34: =D34/D$44*100 -> 13.087269 | F34: =F35+F37 -> 68355 | G34: =F34/F$44*100 -> 12.853606 | I34: =(D34-B34)/B34*100 -> 5 | J34: =(F34-D34)/D34*100 -> 5 | K34: =D34-B34 -> 3100 | L34: =F34-D34 -> 3255
A35: =ACTIVA!A35 -> Handelsvorderingen | B35: =ACTIVA!B35 -> 62000 | C35: =B35/B$44*100 -> 13.08487 | D35: =ACTIVA!D35 -> 65100 | E35: =D35/D$44*100 -> 13.087269 | F35: =ACTIVA!F35 -> 68355 | G35: =F35/F$44*100 -> 12.853606 | I35: =(D35-B35)/B35*100 -> 5 | J35: =(F35-D35)/D35*100 -> 5 | K35: =D35-B35 -> 3100 | L35: =F35-D35 -> 3255
A36: =ACTIVA!A36 -> Overige Vorderingen | C36: =B36/B$44*100 -> 0 | E36: =D36/D$44*100 -> 0 | G36: =F36/F$44*100 -> 0 | I36: =(D36-B36)/B36*100 -> #DIV/0! | J36: =(F36-D36)/D36*100 -> #DIV/0! | K36: =D36-B36 -> 0 | L36: =F36-D36 -> 0
A37: =ACTIVA!A37 -> BTW | B37: =ACTIVA!B37 -> 0 | C37: =B37/B$44*100 -> 0 | D37: =ACTIVA!D37 -> 0 | E37: =D37/D$44*100 -> 0 | F37: =ACTIVA!F37 -> 0 | G37: =F37/F$44*100 -> 0 | I37: =(D37-B37)/B37*100 -> #DIV/0! | J37: =(F37-D37)/D37*100 -> #DIV/0! | K37: =D37-B37 -> 0 | L37: =F37-D37 -> 0
A39: =ACTIVA!A39 -> Liquide Middelen | B39: =B40 -> 107829.71 | C39: =B39/B$44*100 -> 22.75706 | D39: =D40 -> 170329.99 | E39: =D39/D$44*100 -> 34.242003 | F39: =F40 -> 243441.31 | G39: =F39/F$44*100 -> 45.777171 | I39: =(D39-B39)/B39*100 -> 57.962025 | J39: =(F39-D39)/D39*100 -> 42.923335 | K39: =D39-B39 -> 62500.284 | L39: =F39-D39 -> 73111.314
A40: =ACTIVA!A40 -> Bank | B40: =ACTIVA!B40 -> 107829.71 | C40: =B40/B$44*100 -> 22.75706 | D40: =ACTIVA!D40 -> 170329.99 | E40: =D40/D$44*100 -> 34.242003 | F40: =ACTIVA!F40 -> 243441.31 | G40: =F40/F$44*100 -> 45.777171 | I40: =(D40-B40)/B40*100 -> 57.962025 | J40: =(F40-D40)/D40*100 -> 42.923335 | K40: =D40-B40 -> 62500.284 | L40: =F40-D40 -> 73111.314
A42: =ACTIVA!A42 -> Overlopende rekeningen | B42: =ACTIVA!B42 -> 0 | C42: =B42/B$44*100 -> 0 | E42: =D42/D$44*100 -> 0 | G42: =F42/F$44*100 -> 0 | I42: =(D42-B42)/B42*100 -> #DIV/0! | J42: =(F42-D42)/D42*100 -> #DIV/0! | K42: =D42-B42 -> 0 | L42: =F42-D42 -> 0
A44: TOTAAL ACTIVA | B44: =B26+B8+B6 -> 473829.71 | C44: 100 | D44: =D26+D8+D6 -> 497429.99 | E44: 100 | F44: =F26+F8+F6 -> 531796.31 | G44: 100 | I44: =(D44-B44)/B44*100 -> 4.9807522 | J44: =(F44-D44)/D44*100 -> 6.9087739 | K44: =D44-B44 -> 23600.284 | L44: =F44-D44 -> 34366.314

Sheet PASSIVA
A1: =ACTIVA!A1 -> VDO
A2: =ACTIVA!A2 -> BALANS NA WINSTVERDELING
A4: PASSIVA | B4: =ACTIVA!B4 -> Jaar 1 | D4: =ACTIVA!D4 -> Jaar 2 | F4: =ACTIVA!F4 -> Jaar 3 | I4: Mutaties in % | K4: Mutaties
C5: % | E5: % | G5: % | I5: jaar 1 -> 2 | J5: jaar 2 -> 3 | K5: jaar 1 -> 2 | L5: jaar 2 -> 3
A6: EIGEN VERMOGEN | B6: =B8+B14+B19+B12+B21 -> 136949.77 | C6: =B6/B58*100 -> 28.902741 | D6: =D8+D14+D19+D12+D21 -> 180601.35 | E6: =D6/D58*100 -> 36.306889 | F6: =F8+F14+F19+F12+F21 -> 232233.16 | G6: =F6/F58*100 -> 43.66957 | I6: =(D6-B6)/B6*100 -> 31.874153 | J6: =(F6-D6)/D6*100 -> 28.588825 | K6: =D6-B6 -> 43651.581 | L6: =F6-D6 -> 51631.805
A8: Inbreng | B8: =SUM(B9:B10) -> 90000 | C8: =B8/B$58*100 -> 18.994166 | D8: =SUM(D9:D10) -> 90000 | E8: =D8/D$58*100 -> 18.092998 | F8: =SUM(F9:F10) -> 90000 | G8: =F8/F$58*100 -> 16.923773 | I8: =(D8-B8)/B8*100 -> 0 | J8: =(F8-D8)/D8*100 -> 0 | K8: =D8-B8 -> 0 | L8: =F8-D8 -> 0
A9: Beschikbaar | B9: =OPGAVE!B3 -> 90000 | C9: =B9/B$58*100 -> 18.994166 | D9: =B9 -> 90000 | E9: =D9/D$58*100 -> 18.092998 | F9: =D9 -> 90000 | G9: =F9/F$58*100 -> 16.923773 | I9: =(D9-B9)/B9*100 -> 0 | J9: =(F9-D9)/D9*100 -> 0 | K9: =D9-B9 -> 0 | L9: =F9-D9 -> 0
A10: Onbeschikbaar | C10: =B10/B$58*100 -> 0 | D10: =B31+B10 -> 0 | E10: =D10/D$58*100 -> 0 | F10: =D10 -> 0 | G10: =F10/F$58*100 -> 0 | I10: =(D10-B10)/B10*100 -> #DIV/0! | J10: =(F10-D10)/D10*100 -> #DIV/0! | K10: =D10-B10 -> 0 | L10: =F10-D10 -> 0
A12: Herwaarderingsmeerwaarden | C12: =B12/B$58*100 -> 0 | E12: =D12/D$58*100 -> 0 | G12: =F12/F$58*100 -> 0 | I12: =(D12-B12)/B12*100 -> #DIV/0! | J12: =(F12-D12)/D12*100 -> #DIV/0! | K12: =D12-B12 -> 0 | L12: =F12-D12 -> 0
A14: Reserves | B14: =SUM(B15:B17) -> 0 | C14: =B14/B$58*100 -> 0 | D14: =SUM(D15:D17) -> 0 | E14: =D14/D$58*100 -> 0 | F14: =SUM(F15:F17) -> 0 | G14: =F14/F$58*100 -> 0 | I14: =(D14-B14)/B14*100 -> #DIV/0! | J14: =(F14-D14)/D14*100 -> #DIV/0! | K14: =D14-B14 -> 0 | L14: =F14-D14 -> 0
A15: Onbeschikbare Reserves | C15: =B15/B$58*100 -> 0 | E15: =D15/D$58*100 -> 0 | G15: =F15/F$58*100 -> 0 | I15: =(D15-B15)/B15*100 -> #DIV/0! | J15: =(F15-D15)/D15*100 -> #DIV/0! | K15: =D15-B15 -> 0 | L15: =F15-D15 -> 0
A16: Belastingvrije Reserves | C16: =B16/B$58*100 -> 0 | E16: =D16/D$58*100 -> 0 | F16: =RESULTAAT!D57 -> 0 | G16: =F16/F$58*100 -> 0 | I16: =(D16-B16)/B16*100 -> #DIV/0! | J16: =(F16-D16)/D16*100 -> #DIV/0! | K16: =D16-B16 -> 0 | L16: =F16-D16 -> 0
A17: Beschikbare Reserves | C17: =B17/B$58*100 -> 0 | E17: =D17/D$58*100 -> 0 | G17: =F17/F$58*100 -> 0 | I17: =(D17-B17)/B17*100 -> #DIV/0! | J17: =(F17-D17)/D17*100 -> #DIV/0! | K17: =D17-B17 -> 0 | L17: =F17-D17 -> 0
A19: Overgedragen Resultaat | B19: =RESULTAAT!B54 -> 46949.774 | C19: =B19/B$58*100 -> 9.9085754 | D19: =RESULTAAT!C75 -> 90601.355 | E19: =D19/D$58*100 -> 18.213891 | F19: =RESULTAAT!D75 -> 142233.16 | G19: =F19/F$58*100 -> 26.745797 | I19: =(D19-B19)/B19*100 -> 92.975061 | J19: =(F19-D19)/D19*100 -> 56.987896 | K19: =D19-B19 -> 43651.581 | L19: =F19-D19 -> 51631.805
A21: Kapitaalsubsidies | C21: =B21/B$58*100 -> 0 | E21: =D21/D$58*100 -> 0 | G21: =F21/F$58*100 -> 0 | I21: =(D21-B21)/B21*100 -> #DIV/0! | J21: =(F21-D21)/D21*100 -> #DIV/0! | K21: =D21-B21 -> 0 | L21: =F21-D21 -> 0
A23: VOORZIENINGEN EN UITGESTELDE BELASTING | B23: =SUM(B25:B26) -> 0 | C23: =B23/B$58*100 -> 0 | D23: =SUM(D25:D26) -> 0 | E23: =D23/D$58*100 -> 0 | F23: =SUM(F25:F26) -> 0 | G23: =F23/F$58*100 -> 0 | I23: =(D23-B23)/B23*100 -> #DIV/0! | J23: =(F23-D23)/D23*100 -> #DIV/0! | K23: =D23-B23 -> 0 | L23: =F23-D23 -> 0
A25: Voorzieningen | C25: =B25/B$58*100 -> 0 | E25: =D25/D$58*100 -> 0 | G25: =F25/F$58*100 -> 0 | I25: =(D25-B25)/B25*100 -> #DIV/0! | J25: =(F25-D25)/D25*100 -> #DIV/0! | K25: =D25-B25 -> 0 | L25: =F25-D25 -> 0
A26: Uitgestelde Belastingen | C26: =B26/B$58*100 -> 0 | E26: =D26/D$58*100 -> 0 | F26: =RESULTAAT!D51 -> 0 | G26: =F26/F$58*100 -> 0 | I26: =(D26-B26)/B26*100 -> #DIV/0! | J26: =(F26-D26)/D26*100 -> #DIV/0! | K26: =D26-B26 -> 0 | L26: =F26-D26 -> 0
A28: SCHULDEN OP + 1 JAAR | B28: =B30 -> 228120.77 | C28: =B28/B$58*100 -> 48.144041 | D28: =D30 -> 204628.06 | E28: =D28/D$58*100 -> 41.137056 | F28: =F30 -> 179933.41 | G28: =F28/F$58*100 -> 33.835025 | I28: =(D28-B28)/B28*100 -> -10.298367 | J28: =(F28-D28)/D28*100 -> -12.068064 | K28: =D28-B28 -> -23492.713 | L28: =F28-D28 -> -24694.645
A30: Financiële Schulden | B30: =SUM(B31:B33) -> 228120.77 | C30: =B30/B$58*100 -> 48.144041 | D30: =SUM(D31:D33) -> 204628.06 | E30: =D30/D$58*100 -> 41.137056 | F30: =SUM(F31:F33) -> 179933.41 | G30: =F30/F$58*100 -> 33.835025 | I30: =(D30-B30)/B30*100 -> -10.298367 | J30: =(F30-D30)/D30*100 -> -12.068064 | K30: =D30-B30 -> -23492.713 | L30: =F30-D30 -> -24694.645
A31: Achtergestelde Lening | C31: =B31/B$58*100 -> 0 | E31: =D31/D$58*100 -> 0 | G31: =F31/F$58*100 -> 0 | I31: =(D31-B31)/B31*100 -> #DIV/0! | J31: =(F31-D31)/D31*100 -> #DIV/0! | K31: =D31-B31 -> 0 | L31: =F31-D31 -> 0
A32: Lening Machines | B32: =Aflossingstabel!J25 -> 228120.77 | C32: =B32/B$58*100 -> 48.144041 | D32: =B32-D38 -> 204628.06 | E32: =D32/D$58*100 -> 41.137056 | F32: =D32-F38 -> 179933.41 | G32: =F32/F$58*100 -> 33.835025 | I32: =(D32-B32)/B32*100 -> -10.298367 | J32: =(F32-D32)/D32*100 -> -12.068064 | K32: =D32-B32 -> -23492.713 | L32: =F32-D32 -> -24694.645
A33: Overige | C33: =B33/B$58*100 -> 0 | E33: =D33/D$58*100 -> 0 | G33: =F33/F$58*100 -> 0 | I33: =(D33-B33)/B33*100 -> #DIV/0! | J33: =(F33-D33)/D33*100 -> #DIV/0! | K33: =D33-B33 -> 0 | L33: =F33-D33 -> 0
A35: SCHULDEN OP - 1 JAAR | B35: =B37+B45+B48+B53+B56+B41 -> 108759.17 | C35: =B35/B$58*100 -> 22.953218 | D35: =D37+D45+D48+D53+D56+D41 -> 112200.58 | E35: =D35/D$58*100 -> 22.556055 | F35: =F37+F45+F48+F53+F56+F41 -> 119629.73 | G35: =F35/F$58*100 -> 22.495405 | I35: =(D35-B35)/B35*100 -> 3.1642537 | J35: =(F35-D35)/D35*100 -> 6.6213141 | K35: =D35-B35 -> 3441.4159 | L35: =F35-D35 -> 7429.1529
A37: Schulden + 1 jaar die binnen het jaar vervallen | B37: =SUM(B38:B39) -> 22349.281 | C37: =B37/B$58*100 -> 4.7167328 | D37: =SUM(D38:D39) -> 23492.713 | E37: =D37/D$58*100 -> 4.722818 | F37: =SUM(F38:F39) -> 24694.645 | G37: =F37/F$58*100 -> 4.6436285 | I37: =(D37-B37)/B37*100 -> 5.1161898 | J37: =(F37-D37)/D37*100 -> 5.1161898 | K37: =D37-B37 -> 1143.4317 | L37: =F37-D37 -> 1201.9318
A38: =A32 -> Lening Machines | B38: =Aflossingstabel!K25 -> 22349.281 | C38: =B38/B$58*100 -> 4.7167328 | D38: =Aflossingstabel!K26 -> 23492.713 | E38: =D38/D$58*100 -> 4.722818 | F38: =Aflossingstabel!K27 -> 24694.645 | G38: =F38/F$58*100 -> 4.6436285 | I38: =(D38-B38)/B38*100 -> 5.1161898 | J38: =(F38-D38)/D38*100 -> 5.1161898 | K38: =D38-B38 -> 1143.4317 | L38: =F38-D38 -> 1201.9318
A39: =A33 -> Overige | C39: =B39/B$58*100 -> 0 | E39: =D39/D$58*100 -> 0 | G39: =F39/F$58*100 -> 0 | I39: =(D39-B39)/B39*100 -> #DIV/0! | J39: =(F39-D39)/D39*100 -> #DIV/0! | K39: =D39-B39 -> 0 | L39: =F39-D39 -> 0
A41: =A30 -> Financiële Schulden | B41: =B42+B43 -> 0 | C41: =B41/B$58*100 -> 0 | D41: =D42+D43 -> 0 | E41: =D41/D$58*100 -> 0 | F41: =F42+F43 -> 0 | G41: =F41/F$58*100 -> 0 | I41: =(D41-B41)/B41*100 -> #DIV/0! | J41: =(F41-D41)/D41*100 -> #DIV/0! | K41: =D41-B41 -> 0 | L41: =F41-D41 -> 0
A42: Kredietinstellingen R/C | C42: =B42/B$58*100 -> 0 | E42: =D42/D$58*100 -> 0 | G42: =F42/F$58*100 -> 0 | I42: =(D42-B42)/B42*100 -> #DIV/0! | J42: =(F42-D42)/D42*100 -> #DIV/0! | K42: =D42-B42 -> 0 | L42: =F42-D42 -> 0
A43: Overige | C43: =B43/B$58*100 -> 0 | E43: =D43/D$58*100 -> 0 | G43: =F43/F$58*100 -> 0 | I43: =(D43-B43)/B43*100 -> #DIV/0! | J43: =(F43-D43)/D43*100 -> #DIV/0! | K43: =D43-B43 -> 0 | L43: =F43-D43 -> 0
A45: Handelsschulden | B45: =B46 -> 69750 | C45: =B45/B$58*100 -> 14.720478 | D45: =D46 -> 73237.5 | E45: =D45/D$58*100 -> 14.723177 | F45: =F46 -> 76899.375 | G45: =F45/F$58*100 -> 14.460306 | I45: =(D45-B45)/B45*100 -> 5 | J45: =(F45-D45)/D45*100 -> 5 | K45: =D45-B45 -> 3487.5 | L45: =F45-D45 -> 3661.875
A46: Leveranciers | B46: ='70-40-44-55'!D28 -> 69750 | C46: =B46/B$58*100 -> 14.720478 | D46: ='70-40-44-55'!D32 -> 73237.5 | E46: =D46/D$58*100 -> 14.723177 | F46: ='70-40-44-55'!D36 -> 76899.375 | G46: =F46/F$58*100 -> 14.460306 | I46: =(D46-B46)/B46*100 -> 5 | J46: =(F46-D46)/D46*100 -> 5 | K46: =D46-B46 -> 3487.5 | L46: =F46-D46 -> 3661.875
A48: Belastingen en Sociale Schulden | B48: =SUM(B49:B51) -> 15649.925 | C48: =B48/B$58*100 -> 3.3028585 | D48: =SUM(D49:D51) -> 14550.527 | E48: =D48/D$58*100 -> 2.9251407 | F48: =SUM(F49:F51) -> 17210.602 | G48: =F48/F$58*100 -> 3.2363147 | I48: =(D48-B48)/B48*100 -> -7.024939 | J48: =(F48-D48)/D48*100 -> 18.281639 | K48: =D48-B48 -> -1099.3977 | L48: =F48-D48 -> 2660.0748
A49: Belastingen | B49: =RESULTAAT!B52 -> 15649.925 | C49: =B49/B$58*100 -> 3.3028585 | D49: =RESULTAAT!C52 -> 14550.527 | E49: =D49/D$58*100 -> 2.9251407 | F49: =RESULTAAT!D52 -> 17210.602 | G49: =F49/F$58*100 -> 3.2363147 | I49: =(D49-B49)/B49*100 -> -7.024939 | J49: =(F49-D49)/D49*100 -> 18.281639 | K49: =D49-B49 -> -1099.3977 | L49: =F49-D49 -> 2660.0748
A50: BTW
A51: Bezoldigingen en Sociale lasten | C51: =B51/B$58*100 -> 0 | E51: =D51/D$58*100 -> 0 | G51: =F51/F$58*100 -> 0 | I51: =(D51-B51)/B51*100 -> #DIV/0! | J51: =(F51-D51)/D51*100 -> #DIV/0! | K51: =D51-B51 -> 0 | L51: =F51-D51 -> 0
A53: Overige | B53: =B54 -> 0 | C53: =B53/B$58*100 -> 0 | D53: =D54 -> 0 | E53: =D53/D$58*100 -> 0 | F53: =F54 -> 0 | G53: =F53/F$58*100 -> 0 | I53: =(D53-B53)/B53*100 -> #DIV/0! | J53: =(F53-D53)/D53*100 -> #DIV/0! | K53: =D53-B53 -> 0 | L53: =F53-D53 -> 0
A54: Overige schulden | C54: =B54/B$58*100 -> 0 | D54: =B54 -> 0 | E54: =D54/D$58*100 -> 0 | F54: =D54 -> 0 | G54: =F54/F$58*100 -> 0 | I54: =(D54-B54)/B54*100 -> #DIV/0! | J54: =(F54-D54)/D54*100 -> #DIV/0! | K54: =D54-B54 -> 0 | L54: =F54-D54 -> 0
A56: Overlopende Rekeningen | B56: =Aflossingstabel!J44 -> 1009.9599 | C56: =B56/B$58*100 -> 0.21314828 | D56: =Aflossingstabel!J45 -> 919.84181 | E56: =D56/D$58*100 -> 0.18491885 | F56: =Aflossingstabel!J46 -> 825.11313 | G56: =F56/F$58*100 -> 0.15515586 | I56: =(D56-B56)/B56*100 -> -8.9229356 | J56: =(F56-D56)/D56*100 -> -10.298367 | K56: =D56-B56 -> -90.11807 | L56: =F56-D56 -> -94.728682
A58: TOTAAL PASSIVA | B58: =B35+B28+B6 -> 473829.71 | C58: 100 | D58: =D35+D28+D6 -> 497429.99 | E58: 100 | F58: =F35+F28+F6+F23 -> 531796.31 | G58: 100 | I58: =(D58-B58)/B58*100 -> 4.9807522 | J58: =(F58-D58)/D58*100 -> 6.9087739 | K58: =D58-B58 -> 23600.284 | L58: =F58-D58 -> 34366.314

Sheet PASSIVA analyse
A1: =ACTIVA!A1 -> VDO
A2: =ACTIVA!A2 -> BALANS NA WINSTVERDELING
C4: VERTIKALE ANALYSE | I4: HORIZONTALE ANALYSE
A5: PASSIVA | B5: =ACTIVA!B4 -> Jaar 1 | C5: ='ACTIVA analyse'!C4 -> Jaar 1 | D5: ='ACTIVA analyse'!D4 -> Jaar 2 | E5: ='ACTIVA analyse'!E4 -> Jaar 2 | F5: ='ACTIVA analyse'!F4 -> Jaar 3 | G5: ='ACTIVA analyse'!G4 -> Jaar 3 | I5: Mutaties in % | K5: Mutaties
C6: % | E6: % | G6: % | I6: jaar 1 -> 2 | J6: jaar 2 -> 3 | K6: jaar 1 -> 2 | L6: jaar 2 -> 3
A7: EIGEN VERMOGEN | B7: =B9+B15+B20+B13+B22 -> 136949.77 | C7: =B7/B59*100 -> 28.902741 | D7: =D9+D15+D20+D13+D22 -> 180601.35 | E7: =D7/D59*100 -> 36.306889 | F7: =F9+F15+F20+F13+F22 -> 232233.16 | G7: =F7/F59*100 -> 43.66957 | I7: =(D7-B7)/B7*100 -> 31.874153 | J7: =(F7-D7)/D7*100 -> 28.588825 | K7: =D7-B7 -> 43651.581 | L7: =F7-D7 -> 51631.805
A9: =PASSIVA!A8 -> Inbreng | B9: =SUM(B10:B11) -> 90000 | C9: =B9/B$59*100 -> 18.994166 | D9: =SUM(D10:D11) -> 90000 | E9: =D9/D$59*100 -> 18.092998 | F9: =SUM(F10:F11) -> 90000 | G9: =F9/F$59*100 -> 16.923773 | I9: =(D9-B9)/B9*100 -> 0 | J9: =(F9-D9)/D9*100 -> 0 | K9: =D9-B9 -> 0 | L9: =F9-D9 -> 0
A10: =PASSIVA!A9 -> Beschikbaar | B10: =PASSIVA!B9 -> 90000 | C10: =B10/B$59*100 -> 18.994166 | D10: =PASSIVA!D9 -> 90000 | E10: =D10/D$59*100 -> 18.092998 | F10: =PASSIVA!F9 -> 90000 | G10: =F10/F$59*100 -> 16.923773 | I10: =(D10-B10)/B10*100 -> 0 | J10: =(F10-D10)/D10*100 -> 0 | K10: =D10-B10 -> 0 | L10: =F10-D10 -> 0
A11: =PASSIVA!A10 -> Onbeschikbaar | B11: =PASSIVA!B10 -> 0 | C11: =B11/B$59*100 -> 0 | D11: =PASSIVA!D10 -> 0 | E11: =D11/D$59*100 -> 0 | F11: =PASSIVA!F10 -> 0 | G11: =F11/F$59*100 -> 0 | I11: =(D11-B11)/B11*100 -> #DIV/0! | J11: =(F11-D11)/D11*100 -> #DIV/0! | K11: =D11-B11 -> 0 | L11: =F11-D11 -> 0
A13: =PASSIVA!A12 -> Herwaarderingsmeerwaarden | B13: =PASSIVA!B12 -> 0 | C13: =B13/B$59*100 -> 0 | D13: =PASSIVA!D12 -> 0 | E13: =D13/D$59*100 -> 0 | F13: =PASSIVA!F12 -> 0 | G13: =F13/F$59*100 -> 0 | I13: =(D13-B13)/B13*100 -> #DIV/0! | J13: =(F13-D13)/D13*100 -> #DIV/0! | K13: =D13-B13 -> 0 | L13: =F13-D13 -> 0
A15: =PASSIVA!A14 -> Reserves | B15: =SUM(B16:B18) -> 0 | C15: =B15/B$59*100 -> 0 | D15: =SUM(D16:D18) -> 0 | E15: =D15/D$59*100 -> 0 | F15: =SUM(F16:F18) -> 0 | G15: =F15/F$59*100 -> 0 | I15: =(D15-B15)/B15*100 -> #DIV/0! | J15: =(F15-D15)/D15*100 -> #DIV/0! | K15: =D15-B15 -> 0 | L15: =F15-D15 -> 0
A16: =PASSIVA!A15 -> Onbeschikbare Reserves | B16: =PASSIVA!B15 -> 0 | C16: =B16/B$59*100 -> 0 | D16: =PASSIVA!D15 -> 0 | E16: =D16/D$59*100 -> 0 | F16: =PASSIVA!F15 -> 0 | G16: =F16/F$59*100 -> 0 | I16: =(D16-B16)/B16*100 -> #DIV/0! | J16: =(F16-D16)/D16*100 -> #DIV/0! | K16: =D16-B16 -> 0 | L16: =F16-D16 -> 0
A17: =PASSIVA!A16 -> Belastingvrije Reserves | B17: =PASSIVA!B16 -> 0 | C17: =B17/B$59*100 -> 0 | D17: =PASSIVA!D16 -> 0 | E17: =D17/D$59*100 -> 0 | F17: =PASSIVA!F16 -> 0 | G17: =F17/F$59*100 -> 0 | I17: =(D17-B17)/B17*100 -> #DIV/0! | J17: =(F17-D17)/D17*100 -> #DIV/0! | K17: =D17-B17 -> 0 | L17: =F17-D17 -> 0
A18: =PASSIVA!A17 -> Beschikbare Reserves | B18: =PASSIVA!B17 -> 0 | C18: =B18/B$59*100 -> 0 | D18: =PASSIVA!D17 -> 0 | E18: =D18/D$59*100 -> 0 | F18: =PASSIVA!F17 -> 0 | G18: =F18/F$59*100 -> 0 | I18: =(D18-B18)/B18*100 -> #DIV/0! | J18: =(F18-D18)/D18*100 -> #DIV/0! | K18: =D18-B18 -> 0 | L18: =F18-D18 -> 0
A20: =PASSIVA!A19 -> Overgedragen Resultaat | B20: =PASSIVA!B19 -> 46949.774 | C20: =B20/B$59*100 -> 9.9085754 | D20: =PASSIVA!D19 -> 90601.355 | E20: =D20/D$59*100 -> 18.213891 | F20: =PASSIVA!F19 -> 142233.16 | G20: =F20/F$59*100 -> 26.745797 | I20: =(D20-B20)/B20*100 -> 92.975061 | J20: =(F20-D20)/D20*100 -> 56.987896 | K20: =D20-B20 -> 43651.581 | L20: =F20-D20 -> 51631.805
A22: =PASSIVA!A21 -> Kapitaalsubsidies | B22: =PASSIVA!B21 -> 0 | C22: =B22/B$59*100 -> 0 | D22: =PASSIVA!D21 -> 0 | E22: =D22/D$59*100 -> 0 | F22: =PASSIVA!F21 -> 0 | G22: =F22/F$59*100 -> 0 | I22: =(D22-B22)/B22*100 -> #DIV/0! | J22: =(F22-D22)/D22*100 -> #DIV/0! | K22: =D22-B22 -> 0 | L22: =F22-D22 -> 0
A24: VOORZIENINGEN EN UITGESTELDE BELASTING | B24: =SUM(B26:B27) -> 0 | C24: =B24/B$59*100 -> 0 | D24: =SUM(D26:D27) -> 0 | E24: =D24/D$59*100 -> 0 | F24: =SUM(F26:F27) -> 0 | G24: =F24/F$59*100 -> 0 | I24: =(D24-B24)/B24*100 -> #DIV/0! | J24: =(F24-D24)/D24*100 -> #DIV/0! | K24: =D24-B24 -> 0 | L24: =F24-D24 -> 0
A26: =PASSIVA!A25 -> Voorzieningen | B26: =PASSIVA!B25 -> 0 | C26: =B26/B$59*100 -> 0 | D26: =PASSIVA!D25 -> 0 | E26: =D26/D$59*100 -> 0 | F26: =PASSIVA!F25 -> 0 | G26: =F26/F$59*100 -> 0 | I26: =(D26-B26)/B26*100 -> #DIV/0! | J26: =(F26-D26)/D26*100 -> #DIV/0! | K26: =D26-B26 -> 0 | L26: =F26-D26 -> 0
A27: =PASSIVA!A26 -> Uitgestelde Belastingen | B27: =PASSIVA!B26 -> 0 | C27: =B27/B$59*100 -> 0 | D27: =PASSIVA!D26 -> 0 | E27: =D27/D$59*100 -> 0 | F27: =PASSIVA!F26 -> 0 | G27: =F27/F$59*100 -> 0 | I27: =(D27-B27)/B27*100 -> #DIV/0! | J27: =(F27-D27)/D27*100 -> #DIV/0! | K27: =D27-B27 -> 0 | L27: =F27-D27 -> 0
A29: SCHULDEN OP + 1 JAAR | B29: =B31 -> 228120.77 | C29: =B29/B$59*100 -> 48.144041 | D29: =D31 -> 204628.06 | E29: =D29/D$59*100 -> 41.137056 | F29: =F31 -> 179933.41 | G29: =F29/F$59*100 -> 33.835025 | I29: =(D29-B29)/B29*100 -> -10.298367 | J29: =(F29-D29)/D29*100 -> -12.068064 | K29: =D29-B29 -> -23492.713 | L29: =F29-D29 -> -24694.645
A31: =PASSIVA!A30 -> Financiële Schulden | B31: =SUM(B32:B34) -> 228120.77 | C31: =B31/B$59*100 -> 48.144041 | D31: =SUM(D32:D34) -> 204628.06 | E31: =D31/D$59*100 -> 41.137056 | F31: =SUM(F32:F34) -> 179933.41 | G31: =F31/F$59*100 -> 33.835025 | I31: =(D31-B31)/B31*100 -> -10.298367 | J31: =(F31-D31)/D31*100 -> -12.068064 | K31: =D31-B31 -> -23492.713 | L31: =F31-D31 -> -24694.645
A32: =PASSIVA!A31 -> Achtergestelde Lening | B32: =PASSIVA!B31 -> 0 | C32: =B32/B$59*100 -> 0 | D32: =PASSIVA!D31 -> 0 | E32: =D32/D$59*100 -> 0 | F32: =PASSIVA!F31 -> 0 | G32: =F32/F$59*100 -> 0 | I32: =(D32-B32)/B32*100 -> #DIV/0! | J32: =(F32-D32)/D32*100 -> #DIV/0! | K32: =D32-B32 -> 0 | L32: =F32-D32 -> 0
A33: =PASSIVA!A32 -> Lening Machines | B33: =PASSIVA!B32 -> 228120.77 | C33: =B33/B$59*100 -> 48.144041 | D33: =PASSIVA!D32 -> 204628.06 | E33: =D33/D$59*100 -> 41.137056 | F33: =PASSIVA!F32 -> 179933.41 | G33: =F33/F$59*100 -> 33.835025 | I33: =(D33-B33)/B33*100 -> -10.298367 | J33: =(F33-D33)/D33*100 -> -12.068064 | K33: =D33-B33 -> -23492.713 | L33: =F33-D33 -> -24694.645
A34: =PASSIVA!A33 -> Overige | B34: =PASSIVA!B33 -> 0 | C34: =B34/B$59*100 -> 0 | D34: =PASSIVA!D33 -> 0 | E34: =D34/D$59*100 -> 0 | F34: =PASSIVA!F33 -> 0 | G34: =F34/F$59*100 -> 0 | I34: =(D34-B34)/B34*100 -> #DIV/0! | J34: =(F34-D34)/D34*100 -> #DIV/0! | K34: =D34-B34 -> 0 | L34: =F34-D34 -> 0
A36: SCHULDEN OP - 1 JAAR | B36: =B38+B46+B49+B54+B57+B42 -> 108759.17 | C36: =B36/B$59*100 -> 22.953218 | D36: =D38+D46+D49+D54+D57+D42 -> 112200.58 | E36: =D36/D$59*100 -> 22.556055 | F36: =F38+F46+F49+F54+F57+F42 -> 119629.73 | G36: =F36/F$59*100 -> 22.495405 | I36: =(D36-B36)/B36*100 -> 3.1642537 | J36: =(F36-D36)/D36*100 -> 6.6213141 | K36: =D36-B36 -> 3441.4159 | L36: =F36-D36 -> 7429.1529
A38: =PASSIVA!A37 -> Schulden + 1 jaar die binnen het jaar vervallen | B38: =SUM(B39:B43) -> 22349.281 | C38: =B38/B$59*100 -> 4.7167328 | D38: =SUM(D39:D43) -> 23492.713 | E38: =D38/D$59*100 -> 4.722818 | F38: =SUM(F39:F43) -> 24694.645 | G38: =F38/F$59*100 -> 4.6436285 | I38: =(D38-B38)/B38*100 -> 5.1161898 | J38: =(F38-D38)/D38*100 -> 5.1161898 | K38: =D38-B38 -> 1143.4317 | L38: =F38-D38 -> 1201.9318
A39: =PASSIVA!A38 -> Lening Machines | B39: =PASSIVA!B38 -> 22349.281 | C39: =B39/B$59*100 -> 4.7167328 | D39: =PASSIVA!D38 -> 23492.713 | E39: =D39/D$59*100 -> 4.722818 | F39: =PASSIVA!F38 -> 24694.645 | G39: =F39/F$59*100 -> 4.6436285 | I39: =(D39-B39)/B39*100 -> 5.1161898 | J39: =(F39-D39)/D39*100 -> 5.1161898 | K39: =D39-B39 -> 1143.4317 | L39: =F39-D39 -> 1201.9318
A40: =PASSIVA!A39 -> Overige | B40: =PASSIVA!B39 -> 0 | C40: =B40/B$59*100 -> 0 | D40: =PASSIVA!D39 -> 0 | E40: =D40/D$59*100 -> 0 | F40: =PASSIVA!F39 -> 0 | G40: =F40/F$59*100 -> 0 | I40: =(D40-B40)/B40*100 -> #DIV/0! | J40: =(F40-D40)/D40*100 -> #DIV/0! | K40: =D40-B40 -> 0 | L40: =F40-D40 -> 0
A42: =PASSIVA!A41 -> Financiële Schulden | B42: =B43+B44 -> 0 | C42: =B42/B$59*100 -> 0 | D42: =D43+D44 -> 0 | E42: =D42/D$59*100 -> 0 | F42: =F43+F44 -> 0 | G42: =F42/F$59*100 -> 0 | I42: =(D42-B42)/B42*100 -> #DIV/0! | J42: =(F42-D42)/D42*100 -> #DIV/0! | K42: =D42-B42 -> 0 | L42: =F42-D42 -> 0
A43: =PASSIVA!A42 -> Kredietinstellingen R/C | B43: =PASSIVA!B42 -> 0 | C43: =B43/B$59*100 -> 0 | D43: =PASSIVA!D42 -> 0 | E43: =D43/D$59*100 -> 0 | F43: =PASSIVA!F42 -> 0 | G43: =F43/F$59*100 -> 0 | I43: =(D43-B43)/B43*100 -> #DIV/0! | J43: =(F43-D43)/D43*100 -> #DIV/0! | K43: =D43-B43 -> 0 | L43: =F43-D43 -> 0
A44: =PASSIVA!A43 -> Overige | B44: =PASSIVA!B43 -> 0 | C44: =B44/B$59*100 -> 0 | D44: =PASSIVA!D43 -> 0 | E44: =D44/D$59*100 -> 0 | F44: =PASSIVA!F43 -> 0 | G44: =F44/F$59*100 -> 0 | I44: =(D44-B44)/B44*100 -> #DIV/0! | J44: =(F44-D44)/D44*100 -> #DIV/0! | K44: =D44-B44 -> 0 | L44: =F44-D44 -> 0
A46: =PASSIVA!A45 -> Handelsschulden | B46: =B47 -> 69750 | C46: =B46/B$59*100 -> 14.720478 | D46: =D47 -> 73237.5 | E46: =D46/D$59*100 -> 14.723177 | F46: =F47 -> 76899.375 | G46: =F46/F$59*100 -> 14.460306 | I46: =(D46-B46)/B46*100 -> 5 | J46: =(F46-D46)/D46*100 -> 5 | K46: =D46-B46 -> 3487.5 | L46: =F46-D46 -> 3661.875
A47: =PASSIVA!A46 -> Leveranciers | B47: =PASSIVA!B46 -> 69750 | C47: =B47/B$59*100 -> 14.720478 | D47: =PASSIVA!D46 -> 73237.5 | E47: =D47/D$59*100 -> 14.723177 | F47: =PASSIVA!F46 -> 76899.375 | G47: =F47/F$59*100 -> 14.460306 | I47: =(D47-B47)/B47*100 -> 5 | J47: =(F47-D47)/D47*100 -> 5 | K47: =D47-B47 -> 3487.5 | L47: =F47-D47 -> 3661.875
A49: =PASSIVA!A48 -> Belastingen en Sociale Schulden | B49: =SUM(B50:B52) -> 15649.925 | C49: =B49/B$59*100 -> 3.3028585 | D49: =SUM(D50:D52) -> 14550.527 | E49: =D49/D$59*100 -> 2.9251407 | F49: =SUM(F50:F52) -> 17210.602 | G49: =F49/F$59*100 -> 3.2363147 | I49: =(D49-B49)/B49*100 -> -7.024939 | J49: =(F49-D49)/D49*100 -> 18.281639 | K49: =D49-B49 -> -1099.3977 | L49: =F49-D49 -> 2660.0748
A50: =PASSIVA!A49 -> Belastingen | B50: =PASSIVA!B49 -> 15649.925 | C50: =B50/B$59*100 -> 3.3028585 | D50: =PASSIVA!D49 -> 14550.527 | E50: =D50/D$59*100 -> 2.9251407 | F50: =PASSIVA!F49 -> 17210.602 | G50: =F50/F$59*100 -> 3.2363147 | I50: =(D50-B50)/B50*100 -> -7.024939 | J50: =(F50-D50)/D50*100 -> 18.281639 | K50: =D50-B50 -> -1099.3977 | L50: =F50-D50 -> 2660.0748
A51: =PASSIVA!A50 -> BTW | B51: =PASSIVA!B50 -> 0 | C51: =B51/B$59*100 -> 0 | D51: =PASSIVA!D50 -> 0 | E51: =D51/D$59*100 -> 0 | F51: =PASSIVA!F50 -> 0 | G51: =F51/F$59*100 -> 0 | I51: =(D51-B51)/B51*100 -> #DIV/0! | J51: =(F51-D51)/D51*100 -> #DIV/0! | K51: =D51-B51 -> 0 | L51: =F51-D51 -> 0
A52: =PASSIVA!A51 -> Bezoldigingen en Sociale lasten | B52: =PASSIVA!B51 -> 0 | C52: =B52/B$59*100 -> 0 | D52: =PASSIVA!D51 -> 0 | E52: =D52/D$59*100 -> 0 | F52: =PASSIVA!F51 -> 0 | G52: =F52/F$59*100 -> 0 | I52: =(D52-B52)/B52*100 -> #DIV/0! | J52: =(F52-D52)/D52*100 -> #DIV/0! | K52: =D52-B52 -> 0 | L52: =F52-D52 -> 0
A54: =PASSIVA!A53 -> Overige | B54: =B55 -> 0 | C54: =B54/B$59*100 -> 0 | D54: =D55 -> 0 | E54: =D54/D$59*100 -> 0 | F54: =F55 -> 0 | G54: =F54/F$59*100 -> 0 | I54: =(D54-B54)/B54*100 -> #DIV/0! | J54: =(F54-D54)/D54*100 -> #DIV/0! | K54: =D54-B54 -> 0 | L54: =F54-D54 -> 0
A55: =PASSIVA!A54 -> Overige schulden | B55: =PASSIVA!B54 -> 0 | C55: =B55/B$59*100 -> 0 | D55: =PASSIVA!D54 -> 0 | E55: =D55/D$59*100 -> 0 | F55: =PASSIVA!F54 -> 0 | G55: =F55/F$59*100 -> 0 | I55: =(D55-B55)/B55*100 -> #DIV/0! | J55: =(F55-D55)/D55*100 -> #DIV/0! | K55: =D55-B55 -> 0 | L55: =F55-D55 -> 0
A57: =PASSIVA!A56 -> Overlopende Rekeningen | B57: =PASSIVA!B56 -> 1009.9599 | C57: =B57/B$59*100 -> 0.21314828 | D57: =PASSIVA!D56 -> 919.84181 | E57: =D57/D$59*100 -> 0.18491885 | F57: =PASSIVA!F56 -> 825.11313 | G57: =F57/F$59*100 -> 0.15515586 | I57: =(D57-B57)/B57*100 -> -8.9229356 | J57: =(F57-D57)/D57*100 -> -10.298367 | K57: =D57-B57 -> -90.11807 | L57: =F57-D57 -> -94.728682
...

Sheet RESULTAAT
A1: =PASSIVA!A1 -> VDO | L1: op balans terug te vinden
A2: RESULTATENREKENING | L2: bedrag of breuk ingeven
A4: BEDRIJFSOPBRENGSTEN | B4: =PASSIVA!B4 -> Jaar 1 | C4: =ACTIVA!D4 -> Jaar 2 | D4: =ACTIVA!F4 -> Jaar 3 | G4: Mutaties in % | K4: jaar 1 | M4: jaar 2 | O4: jaar 3
B5: =B8+B12+B15 -> 945000 | C5: =C8+C12+C15 -> 976500 | D5: =D8+D12+D15 -> 1025325 | G5: =(C5-B5)/B5*100 -> 3.3333333 | H5: =(D5-C5)/C5*100 -> 5 | K5: 411 | L5: 451 | M5: 411 | N5: 451 | O5: 411 | P5: 451
A7: Recurrente Bedrijfsopbrengsten | B7: =B8+B12 -> 945000 | C7: =C8+C12 -> 976500 | D7: =D8+D12 -> 1025325 | E7: 100 | G7: =(C7-B7)/B7*100 -> 3.3333333 | H7: =(D7-C7)/C7*100 -> 5 | J7: totaal | K7: =(B20+B21+B24)*21% -> 154669.87 | L7: =B8*21% -> 195300 | M7: =(C20+C21+C24)*21% -> 162038.42 | N7: =C8*21% -> 205065 | O7: =(D20+D21+D24)*21% -> 169898.53 | P7: =D8*21% -> 215318.25
A8: Omzet | B8: =SUM(B9:B10) -> 930000 | C8: =SUM(C9:C10) -> 976500 | D8: =SUM(D9:D10) -> 1025325 | G8: =(C8-B8)/B8*100 -> 5 | H8: =(D8-C8)/C8*100 -> 5 | J8: saldo | L8: =L7-K7 -> 40630.128 | N8: =N7-M7 -> 43026.581 | P8: =P7-O7 -> 45419.715
A9: Omzet | B9: ='70-40-44-55'!C2 -> 930000 | C9: ='70-40-44-55'!C3 -> 976500 | D9: ='70-40-44-55'!C4 -> 1025325 | G9: =(C9-B9)/B9*100 -> 5 | H9: =(D9-C9)/C9*100 -> 5 | J9: rek 451 | L9: =L8/4 -> 10157.532 | N9: =N8/4 -> 10756.645 | P9: =P8/4 -> 11354.929
A10: Omzet | G10: =(C10-B10)/B10*100 -> #DIV/0! | H10: =(D10-C10)/C10*100 -> #DIV/0! | J10: betaald | L10: =L8-L9 -> 30472.596 | N10: =N8-N9 -> 32269.936 | P10: =P8-P9 -> 34064.786
A12: Overige Bedrijfsopbrengsten | B12: =B13 -> 15000 | C12: =C13 -> 0 | D12: =D13 -> 0 | G12: =(C12-B12)/B12*100 -> -100 | H12: =(D12-C12)/C12*100 -> #DIV/0!
A13: Subsidies | B13: =OPGAVE!B23 -> 15000 | G13: =(C13-B13)/B13*100 -> -100 | H13: =(D13-C13)/C13*100 -> #DIV/0! | J13: VERKOOP | K13: =B8 -> 930000 | M13: =C8 -> 976500 | O13: =D8 -> 1025325
A14: Meerwaarde realisatie vaste activa
A15: Niet recurrente opbrengsten | G15: =(C15-B15)/B15*100 -> #DIV/0! | H15: =(D15-C15)/C15*100 -> #DIV/0! | J15: BTW | K15: =L7 -> 195300 | M15: =N7 -> 205065 | O15: =P7 -> 215318.25
A17: BEDRIJFSKOSTEN | B17: =B19+B24+B26+B28+B33+B37 -> 869418.83 | C17: =C19+C24+C26+C28+C33+C37 -> 906372.06 | D17: =D19+D24+D26+D28+D33+D37 -> 945704.81 | E17: =D17/D7*100 -> 92.234639 | G17: =(C17-B17)/B17*100 -> 4.2503373 | H17: =(D17-C17)/C17*100 -> 4.3395802 | K17: =SUM(K13:K15) -> 1125300 | M17: =SUM(M13:M15) -> 1181565 | O17: =SUM(O13:O15) -> 1240643.2
A19: Aankopen | B19: =SUM(B20:B22) -> 558000 | C19: =SUM(C20:C22) -> 585900 | D19: =SUM(D20:D22) -> 615195 | E19: =D19/D$7*100 -> 60 | G19: =(C19-B19)/B19*100 -> 5 | H19: =(D19-C19)/C19*100 -> 5 | J19: Krediet/m | K19: 0.91666667 | M19: 0.91666667 | O19: 0.91666667
A20: Aankoop Grondstoffen | E20: =D20/D$7*100 -> 0 | G20: =(C20-B20)/B20*100 -> #DIV/0! | H20: =(D20-C20)/C20*100 -> #DIV/0! | J20: betaald | K20: =K17*K19 -> 1031525 | M20: =M17*M19 -> 1083101.2 | O20: =O17*O19 -> 1137256.3
A21: aankoop Handelsgoederen | B21: ='70-40-44-55'!L25 -> 558000 | C21: ='70-40-44-55'!L26 -> 585900 | D21: ='70-40-44-55'!L27 -> 615195 | E21: =D21/D$7*100 -> 60 | G21: =(C21-B21)/B21*100 -> 5 | H21: =(D21-C21)/C21*100 -> 5 | J21: klanten | K21: =K17-K20 -> 93775 | M21: =M17-M20 -> 98463.75 | O21: =O17-O20 -> 103386.94
A22: Voorraadwijziging | E22: =D22/D$7*100 -> 0 | G22: =(C22-B22)/B22*100 -> #DIV/0! | H22: =(D22-C22)/C22*100 -> #DIV/0!
A24: Diensten en Div. Goederen | B24: =DETAILS!B54 -> 178523.2 | C24: =DETAILS!C54 -> 185711.52 | D24: =DETAILS!D54 -> 193845.64 | E24: =D24/D$7*100 -> 18.905775 | G24: =(C24-B24)/B24*100 -> 4.0265467 | H24: =(D24-C24)/C24*100 -> 4.3799771 | J24: 700 | L24: 1200000 | N24: =L24*1.05 -> 1260000 | P24: =N24*1.05 -> 1323000
A26: Personeelskosten | B26: =DETAILS!B74 -> 86195.632 | C26: =DETAILS!C74 -> 87919.545 | D26: =DETAILS!D74 -> 89677.936 | E26: =D26/D$7*100 -> 8.7462937 | G26: =(C26-B26)/B26*100 -> 2 | H26: =(D26-C26)/C26*100 -> 2 | J26: 451 | L26: =K15 -> 195300 | N26: =M15 -> 205065 | P26: =O15 -> 215318.25
A28: Afschrijvingen en waardeverminderingen | B28: =B29+B30+B31 -> 42000 | C28: =C29+C30+C31 -> 42000 | D28: =D29+D30+D31 -> 42000 | E28: =D28/D$7*100 -> 4.0962622 | G28: =(C28-B28)/B28*100 -> 0 | H28: =(D28-C28)/C28*100 -> 0 | J28: 400 | K28: =K21 -> 93775 | M28: =M21 -> 98463.75 | O28: =O21 -> 103386.94
A29: Afschrijvingen | B29: ='INVEST TABEL'!E33 -> 42000 | C29: ='INVEST TABEL'!F33 -> 42000 | D29: ='INVEST TABEL'!G33 -> 42000 | E29: =D29/D$7*100 -> 4.0962622 | G29: =(C29-B29)/B29*100 -> 0 | H29: =(D29-C29)/C29*100 -> 0 | J29: 550 | K29: =K20 -> 1031525 | M29: =M20 -> 1083101.2 | O29: =O20 -> 1137256.3
A30: Waardeverminderingen | E30: =D30/D$7*100 -> 0 | G30: =(C30-B30)/B30*100 -> #DIV/0! | H30: =(D30-C30)/C30*100 -> #DIV/0!
A31: Voorzieningen | E31: =D31/D$7*100 -> 0 | G31: =(C31-B31)/B31*100 -> #DIV/0! | H31: =(D31-C31)/C31*100 -> #DIV/0! | K31: =SUM(K24:K30) -> 1125300 | L31: =SUM(L24:L30) -> 1395300 | M31: =SUM(M24:M30) -> 1181565 | N31: =SUM(N24:N30) -> 1465065 | O31: =SUM(O24:O30) -> 1240643.2 | P31: =SUM(P24:P30) -> 1538318.2
A33: Overige Bedrijfskosten | B33: =B34+B35 -> 4700 | C33: =C34+C35 -> 4841 | D33: =D34+D35 -> 4986.23 | E33: =D33/D$7*100 -> 0.48630727 | G33: =(C33-B33)/B33*100 -> 3 | H33: =(D33-C33)/C33*100 -> 3
A34: Bedrijfsbelastingen | B34: =DETAILS!B91 -> 4700 | C34: =DETAILS!B92 -> 4841 | D34: =DETAILS!B93 -> 4986.23 | E34: =D34/D$7*100 -> 0.48630727 | G34: =(C34-B34)/B34*100 -> 3 | H34: =(D34-C34)/C34*100 -> 3 | J34: AANKOOP | K34: =B20+B21+B24 -> 736523.2 | M34: =C20+C21+C24 -> 771611.52 | O34: =D20+D21+D24 -> 809040.64
A35: Minderwaarde verkoop mva | E35: =D35/D$7*100 -> 0 | G35: =(C35-B35)/B35*100 -> #DIV/0! | H35: =(D35-C35)/C35*100 -> #DIV/0! | J35: BTW | K35: =K7 -> 154669.87 | M35: =M7 -> 162038.42 | O35: =O7 -> 169898.53
A37: Niet recurrente bedrijfskosten | E37: =D37/D$7*100 -> 0 | G37: =(C37-B37)/B37*100 -> #DIV/0! | H37: =(D37-C37)/C37*100 -> #DIV/0! | K37: =SUM(K34:K36) -> 891193.07 | M37: =SUM(M34:M36) -> 933649.94 | O37: =SUM(O34:O36) -> 978939.18
A39: BRUTO TOEGEVOEGDE WAARDE | B39: =B7-B19-B24 -> 208476.8 | C39: =C7-C19-C24 -> 204888.48 | D39: =D7-D19-D24 -> 216284.36 | E39: =D39/D$7*100 -> 21.094225 | G39: =(C39-B39)/B39*100 -> -1.7212083 | H39: =(D39-C39)/C39*100 -> 5.5619906 | J39: krediet/m | K39: 0.91666667 | M39: 0.91666667 | O39: 0.91666667
A40: EBIT | B40: =B5-B17 -> 75581.168 | C40: =C5-C17 -> 70127.935 | D40: =D5-D17 -> 79620.192 | E40: =D40/D$7*100 -> 7.7653615 | G40: =(C40-B40)/B40*100 -> -7.215068 | H40: =(D40-C40)/C40*100 -> 13.535629 | J40: betaald | K40: =K37*K39 -> 816926.98 | M40: =M37*M39 -> 855845.78 | O40: =O37*O39 -> 897360.91
A41: EBITDA | B41: =B40+B29+B30 -> 117581.17 | C41: =C40+C29+C30 -> 112127.94 | D41: =D40+D29+D30 -> 121620.19 | E41: =D41/D$7*100 -> 11.861624 | G41: =(C41-B41)/B41*100 -> -4.6378453 | H41: =(D41-C41)/C41*100 -> 8.4655595 | J41: leverancier | K41: =K37-K40 -> 74266.089 | M41: =M37-M40 -> 77804.162 | O41: =O37-O40 -> 81578.265
A42: BEDRIJFSRESULTAAT | B42: =B5-B17 -> 75581.168 | C42: =C5-C17 -> 70127.935 | D42: =D5-D17 -> 79620.192 | E42: =D42/D$7*100 -> 7.7653615 | G42: =(C42-B42)/B42*100 -> -7.215068 | H42: =(D42-C42)/C42*100 -> 13.535629
A44: Financiële Opbrengsten | E44: =D44/D$7*100 -> 0 | G44: =(C44-B44)/B44*100 -> #DIV/0! | H44: =(D44-C44)/C44*100 -> #DIV/0! | J44: 600 | K44: =B20+B21 -> 558000 | M44: =C20+C21 -> 585900 | O44: =D20+D21 -> 615195
A45: Financiële Kosten | B45: =Aflossingstabel!K13 -> 12981.469 | C45: =Aflossingstabel!K14 -> 11925.827 | D45: =Aflossingstabel!K15 -> 10777.785 | E45: =D45/D$7*100 -> 1.0511579 | G45: =(C45-B45)/B45*100 -> -8.1319143 | H45: =(D45-C45)/C45*100 -> -9.6265209 | J45: 61 | K45: =B24 -> 178523.2 | M45: =C24 -> 185711.52 | O45: =D24 -> 193845.64
A46: Niet recurrent Financieel (+/-) | E46: =D46/D$7*100 -> 0 | G46: =(C46-B46)/B46*100 -> #DIV/0! | H46: =(D46-C46)/C46*100 -> #DIV/0! | J46: 411 | K46: =K35 -> 154669.87 | M46: =M35 -> 162038.42 | O46: =O35 -> 169898.53
A48: RESULTAAT VOOR BELASTING | B48: =B42+B44-B45 -> 62599.699 | C48: =C42+C44-C45 -> 58202.108 | D48: =D42+D44-D45 -> 68842.407 | E48: =D48/D7*100 -> 6.7142035 | G48: =(C48-B48)/B48*100 -> -7.024939 | H48: =(D48-C48)/C48*100 -> 18.281639 | J48: 440 | L48: =K41 -> 74266.089 | N48: =M41 -> 77804.162 | P48: =O41 -> 81578.265
A50: Onttrekking aan de uitgestelde belasting | G50: =(C50-B50)/B50*100 -> #DIV/0! | H50: =(D50-C50)/C50*100 -> #DIV/0! | J50: 550 | L50: =K40 -> 816926.98 | N50: =M40 -> 855845.78 | P50: =O40 -> 897360.91
A51: Overboeking naar de uitgestelde belasting | G51: =(C51-B51)/B51*100 -> #DIV/0! | H51: =(D51-C51)/C51*100 -> #DIV/0!
A52: Belastingen op het resultaat | B52: =B48*25% -> 15649.925 | C52: =C48*25% -> 14550.527 | D52: =D48*25% -> 17210.602 | E52: =D52/D7*100 -> 1.6785509 | G52: =(C52-B52)/B52*100 -> -7.024939 | H52: =(D52-C52)/C52*100 -> 18.281639 | K52: =SUM(K44:K51) -> 891193.07 | L52: =SUM(L44:L50) -> 891193.07 | M52: =SUM(M44:M51) -> 933649.94 | N52: =SUM(N44:N50) -> 933649.94 | O52: =SUM(O44:O51) -> 978939.18 | P52: =SUM(P44:P50) -> 978939.18
A54: NETTO RESULTAAT | B54: =B48+B50-B51-B52 -> 46949.774 | C54: =C48+C50-C51-C52 -> 43651.581 | D54: =D48+D50-D51-D52 -> 51631.805 | E54: =D54/D7*100 -> 5.0356526 | G54: =(C54-B54)/B54*100 -> -7.024939 | H54: =(D54-C54)/C54*100 -> 18.281639 | J54: BTW | K54: 411 | L54: 451 | M54: 411 | N54: 451 | O54: 411 | P54: 451
A56: Onttrekking aan de Belastingvrije Reserves | G56: =(C56-B56)/B56*100 -> #DIV/0! | H56: =(D56-C56)/C56*100 -> #DIV/0! | K56: =K46 -> 154669.87 | L56: =L26 -> 195300 | M56: =M46 -> 162038.42 | N56: =N26 -> 205065 | O56: =O46 -> 169898.53 | P56: =P26 -> 215318.25
...

Sheet RESULTAAT analyse
A1: =PASSIVA!A1 -> VDO
A2: RESULTATENREKENING
C3: HORIZONTALE ANALYSE | I3: VERTIKALE ANALYSE
B4: =PASSIVA!B4 -> Jaar 1 | D4: =PASSIVA!D4 -> Jaar 2 | F4: =PASSIVA!F4 -> Jaar 3 | I4: Mutaties in % | K4: Mutaties
A5: =RESULTAAT!A4 -> BEDRIJFSOPBRENGSTEN | B5: =B8+B12+B15 -> 945000 | D5: =D8+D12+D15 -> 976500 | F5: =F8+F12+F15 -> 1025325 | I5: =(D5-B5)/B5*100 -> 3.3333333 | J5: =(F5-D5)/D5*100 -> 5 | K5: jaar 1 -> 2 | L5: jaar 2 -> 3
A7: =RESULTAAT!A7 -> Recurrente Bedrijfsopbrengsten | B7: =B8+B12 -> 945000 | C7: 100 | D7: =D8+D12 -> 976500 | E7: 100 | F7: =F8+F12 -> 1025325 | G7: 100 | I7: =(D7-B7)/B7*100 -> 3.3333333 | J7: =(F7-D7)/D7*100 -> 5 | K7: =RESULTAAT!C7-RESULTAAT!B7 -> 31500 | L7: =RESULTAAT!D7-RESULTAAT!C7 -> 48825
A8: =RESULTAAT!A8 -> Omzet | B8: =SUM(B9:B10) -> 930000 | D8: =SUM(D9:D10) -> 976500 | F8: =SUM(F9:F10) -> 1025325 | I8: =(D8-B8)/B8*100 -> 5 | J8: =(F8-D8)/D8*100 -> 5 | K8: =RESULTAAT!C8-RESULTAAT!B8 -> 46500 | L8: =RESULTAAT!D8-RESULTAAT!C8 -> 48825
A9: =RESULTAAT!A9 -> Omzet | B9: =RESULTAAT!B9 -> 930000 | D9: =RESULTAAT!C9 -> 976500 | F9: =RESULTAAT!D9 -> 1025325 | I9: =(D9-B9)/B9*100 -> 5 | J9: =(F9-D9)/D9*100 -> 5 | K9: =RESULTAAT!C9-RESULTAAT!B9 -> 46500 | L9: =RESULTAAT!D9-RESULTAAT!C9 -> 48825
A10: =RESULTAAT!A10 -> Omzet | B10: =RESULTAAT!B10 -> 0 | D10: =RESULTAAT!C10 -> 0 | F10: =RESULTAAT!D10 -> 0 | I10: =(D10-B10)/B10*100 -> #DIV/0! | J10: =(F10-D10)/D10*100 -> #DIV/0! | K10: =RESULTAAT!C10-RESULTAAT!B10 -> 0 | L10: =RESULTAAT!D10-RESULTAAT!C10 -> 0
A12: =RESULTAAT!A12 -> Overige Bedrijfsopbrengsten | B12: =B13 -> 15000 | D12: =D13 -> 0 | F12: =F13 -> 0 | I12: =(D12-B12)/B12*100 -> -100 | J12: =(F12-D12)/D12*100 -> #DIV/0! | K12: =RESULTAAT!C12-RESULTAAT!B12 -> -15000 | L12: =RESULTAAT!D12-RESULTAAT!C12 -> 0
A13: =RESULTAAT!A14 -> Meerwaarde realisatie vaste activa | B13: =RESULTAAT!B13 -> 15000 | D13: =RESULTAAT!C13 -> 0 | F13: =RESULTAAT!D13 -> 0 | I13: =(D13-B13)/B13*100 -> -100 | J13: =(F13-D13)/D13*100 -> #DIV/0! | K13: =RESULTAAT!C13-RESULTAAT!B13 -> -15000 | L13: =RESULTAAT!D13-RESULTAAT!C13 -> 0
A15: =RESULTAAT!A15 -> Niet recurrente opbrengsten | B15: =RESULTAAT!B15 -> 0 | D15: =RESULTAAT!C15 -> 0 | F15: =RESULTAAT!D15 -> 0 | I15: =(D15-B15)/B15*100 -> #DIV/0! | J15: =(F15-D15)/D15*100 -> #DIV/0! | K15: =RESULTAAT!C15-RESULTAAT!B15 -> 0 | L15: =RESULTAAT!D15-RESULTAAT!C15 -> 0
A17: =RESULTAAT!A17 -> BEDRIJFSKOSTEN | B17: =B19+B24+B26+B28+B33+B37 -> 869418.83 | C17: =RESULTAAT!B17/RESULTAAT!B$7*100 -> 92.001993 | D17: =D19+D24+D26+D28+D33+D37 -> 906372.06 | E17: =D17/D7*100 -> 92.81844 | F17: =F19+F24+F26+F28+F33+F37 -> 945704.81 | G17: =F17/F7*100 -> 92.234639 | I17: =(D17-B17)/B17*100 -> 4.2503373 | J17: =(F17-D17)/D17*100 -> 4.3395802 | K17: =RESULTAAT!C17-RESULTAAT!B17 -> 36953.233 | L17: =RESULTAAT!D17-RESULTAAT!C17 -> 39332.743
A19: =RESULTAAT!A19 -> Aankopen | B19: =SUM(B20:B22) -> 558000 | C19: =RESULTAAT!B19/RESULTAAT!B$7*100 -> 59.047619 | D19: =SUM(D20:D22) -> 585900 | E19: =D19/D$7*100 -> 60 | F19: =SUM(F20:F22) -> 615195 | G19: =F19/F$7*100 -> 60 | I19: =(D19-B19)/B19*100 -> 5 | J19: =(F19-D19)/D19*100 -> 5 | K19: =RESULTAAT!C19-RESULTAAT!B19 -> 27900 | L19: =RESULTAAT!D19-RESULTAAT!C19 -> 29295
A20: =RESULTAAT!A20 -> Aankoop Grondstoffen | B20: =RESULTAAT!B20 -> 0 | C20: =RESULTAAT!B20/RESULTAAT!B$7*100 -> 0 | D20: =RESULTAAT!C20 -> 0 | E20: =D20/D$7*100 -> 0 | F20: =RESULTAAT!D20 -> 0 | G20: =F20/F$7*100 -> 0 | I20: =(D20-B20)/B20*100 -> #DIV/0! | J20: =(F20-D20)/D20*100 -> #DIV/0! | K20: =RESULTAAT!C20-RESULTAAT!B20 -> 0 | L20: =RESULTAAT!D20-RESULTAAT!C20 -> 0
A21: =RESULTAAT!A21 -> aankoop Handelsgoederen | B21: =RESULTAAT!B21 -> 558000 | C21: =RESULTAAT!B21/RESULTAAT!B$7*100 -> 59.047619 | D21: =RESULTAAT!C21 -> 585900 | E21: =D21/D$7*100 -> 60 | F21: =RESULTAAT!D21 -> 615195 | G21: =F21/F$7*100 -> 60 | I21: =(D21-B21)/B21*100 -> 5 | J21: =(F21-D21)/D21*100 -> 5 | K21: =RESULTAAT!C21-RESULTAAT!B21 -> 27900 | L21: =RESULTAAT!D21-RESULTAAT!C21 -> 29295
A22: =RESULTAAT!A22 -> Voorraadwijziging | B22: =RESULTAAT!B22 -> 0 | C22: =RESULTAAT!B22/RESULTAAT!B$7*100 -> 0 | D22: =RESULTAAT!C22 -> 0 | E22: =D22/D$7*100 -> 0 | F22: =RESULTAAT!D22 -> 0 | G22: =F22/F$7*100 -> 0 | I22: =(D22-B22)/B22*100 -> #DIV/0! | J22: =(F22-D22)/D22*100 -> #DIV/0! | K22: =RESULTAAT!C22-RESULTAAT!B22 -> 0 | L22: =RESULTAAT!D22-RESULTAAT!C22 -> 0
A24: =RESULTAAT!A24 -> Diensten en Div. Goederen | B24: =RESULTAAT!B24 -> 178523.2 | C24: =RESULTAAT!B24/RESULTAAT!B$7*100 -> 18.891344 | D24: =RESULTAAT!C24 -> 185711.52 | E24: =D24/D$7*100 -> 19.018077 | F24: =RESULTAAT!D24 -> 193845.64 | G24: =F24/F$7*100 -> 18.905775 | I24: =(D24-B24)/B24*100 -> 4.0265467 | J24: =(F24-D24)/D24*100 -> 4.3799771 | K24: =RESULTAAT!C24-RESULTAAT!B24 -> 7188.32 | L24: =RESULTAAT!D24-RESULTAAT!C24 -> 8134.122
A26: =RESULTAAT!A26 -> Personeelskosten | B26: =RESULTAAT!B26 -> 86195.632 | C26: =RESULTAAT!B26/RESULTAAT!B$7*100 -> 9.1212309 | D26: =RESULTAAT!C26 -> 87919.545 | E26: =D26/D$7*100 -> 9.0035376 | F26: =RESULTAAT!D26 -> 89677.936 | G26: =F26/F$7*100 -> 8.7462937 | I26: =(D26-B26)/B26*100 -> 2 | J26: =(F26-D26)/D26*100 -> 2 | K26: =RESULTAAT!C26-RESULTAAT!B26 -> 1723.9126 | L26: =RESULTAAT!D26-RESULTAAT!C26 -> 1758.3909
A28: =RESULTAAT!A28 -> Afschrijvingen en waardeverminderingen | B28: =B29+B30+B31 -> 42000 | C28: =RESULTAAT!B28/RESULTAAT!B$7*100 -> 4.4444444 | D28: =D29+D30+D31 -> 42000 | E28: =D28/D$7*100 -> 4.3010753 | F28: =F29+F30+F31 -> 42000 | G28: =F28/F$7*100 -> 4.0962622 | I28: =(D28-B28)/B28*100 -> 0 | J28: =(F28-D28)/D28*100 -> 0 | K28: =RESULTAAT!C28-RESULTAAT!B28 -> 0 | L28: =RESULTAAT!D28-RESULTAAT!C28 -> 0
A29: =RESULTAAT!A29 -> Afschrijvingen | B29: =RESULTAAT!B29 -> 42000 | C29: =RESULTAAT!B29/RESULTAAT!B$7*100 -> 4.4444444 | D29: =RESULTAAT!C29 -> 42000 | E29: =D29/D$7*100 -> 4.3010753 | F29: =RESULTAAT!D29 -> 42000 | G29: =F29/F$7*100 -> 4.0962622 | I29: =(D29-B29)/B29*100 -> 0 | J29: =(F29-D29)/D29*100 -> 0 | K29: =RESULTAAT!C29-RESULTAAT!B29 -> 0 | L29: =RESULTAAT!D29-RESULTAAT!C29 -> 0
A30: =RESULTAAT!A30 -> Waardeverminderingen | B30: =RESULTAAT!B30 -> 0 | C30: =RESULTAAT!B30/RESULTAAT!B$7*100 -> 0 | D30: =RESULTAAT!C30 -> 0 | E30: =D30/D$7*100 -> 0 | F30: =RESULTAAT!D30 -> 0 | G30: =F30/F$7*100 -> 0 | I30: =(D30-B30)/B30*100 -> #DIV/0! | J30: =(F30-D30)/D30*100 -> #DIV/0! | K30: =RESULTAAT!C30-RESULTAAT!B30 -> 0 | L30: =RESULTAAT!D30-RESULTAAT!C30 -> 0
A31: =RESULTAAT!A31 -> Voorzieningen | B31: =RESULTAAT!B31 -> 0 | C31: =RESULTAAT!B31/RESULTAAT!B$7*100 -> 0 | D31: =RESULTAAT!C31 -> 0 | E31: =D31/D$7*100 -> 0 | F31: =RESULTAAT!D31 -> 0 | G31: =F31/F$7*100 -> 0 | I31: =(D31-B31)/B31*100 -> #DIV/0! | J31: =(F31-D31)/D31*100 -> #DIV/0! | K31: =RESULTAAT!C31-RESULTAAT!B31 -> 0 | L31: =RESULTAAT!D31-RESULTAAT!C31 -> 0
A33: =RESULTAAT!A33 -> Overige Bedrijfskosten | B33: =B34+B35 -> 4700 | C33: =RESULTAAT!B33/RESULTAAT!B$7*100 -> 0.4973545 | D33: =D34+D35 -> 4841 | E33: =D33/D$7*100 -> 0.49575013 | F33: =F34+F35 -> 4986.23 | G33: =F33/F$7*100 -> 0.48630727 | I33: =(D33-B33)/B33*100 -> 3 | J33: =(F33-D33)/D33*100 -> 3 | K33: =RESULTAAT!C33-RESULTAAT!B33 -> 141 | L33: =RESULTAAT!D33-RESULTAAT!C33 -> 145.23
A34: =RESULTAAT!A34 -> Bedrijfsbelastingen | B34: =RESULTAAT!B34 -> 4700 | C34: =RESULTAAT!B34/RESULTAAT!B$7*100 -> 0.4973545 | D34: =RESULTAAT!C34 -> 4841 | E34: =D34/D$7*100 -> 0.49575013 | F34: =RESULTAAT!D34 -> 4986.23 | G34: =F34/F$7*100 -> 0.48630727 | I34: =(D34-B34)/B34*100 -> 3 | J34: =(F34-D34)/D34*100 -> 3 | K34: =RESULTAAT!C34-RESULTAAT!B34 -> 141 | L34: =RESULTAAT!D34-RESULTAAT!C34 -> 145.23
A35: =RESULTAAT!A35 -> Minderwaarde verkoop mva | B35: =RESULTAAT!B35 -> 0 | C35: =RESULTAAT!B35/RESULTAAT!B$7*100 -> 0 | D35: =RESULTAAT!C35 -> 0 | E35: =D35/D$7*100 -> 0 | F35: =RESULTAAT!D35 -> 0 | G35: =F35/F$7*100 -> 0 | I35: =(D35-B35)/B35*100 -> #DIV/0! | J35: =(F35-D35)/D35*100 -> #DIV/0! | K35: =RESULTAAT!C35-RESULTAAT!B35 -> 0 | L35: =RESULTAAT!D35-RESULTAAT!C35 -> 0
A37: =RESULTAAT!A37 -> Niet recurrente bedrijfskosten | B37: =RESULTAAT!B37 -> 0 | C37: =RESULTAAT!B37/RESULTAAT!B$7*100 -> 0 | D37: =RESULTAAT!C37 -> 0 | E37: =D37/D$7*100 -> 0 | F37: =RESULTAAT!D37 -> 0 | G37: =F37/F$7*100 -> 0 | I37: =(D37-B37)/B37*100 -> #DIV/0! | J37: =(F37-D37)/D37*100 -> #DIV/0! | K37: =RESULTAAT!C37-RESULTAAT!B37 -> 0 | L37: =RESULTAAT!D37-RESULTAAT!C37 -> 0
A39: =RESULTAAT!A39 -> BRUTO TOEGEVOEGDE WAARDE | B39: =B7-B19-B24 -> 208476.8 | C39: =B39/B$7*100 -> 22.061037 | D39: =D7-D19-D24 -> 204888.48 | E39: =D39/D$7*100 -> 20.981923 | F39: =F7-F19-F24 -> 216284.36 | G39: =F39/F$7*100 -> 21.094225 | I39: =(D39-B39)/B39*100 -> -1.7212083 | J39: =(F39-D39)/D39*100 -> 5.5619906 | K39: =RESULTAAT!C39-RESULTAAT!B39 -> -3588.32 | L39: =RESULTAAT!D39-RESULTAAT!C39 -> 11395.878
A40: =RESULTAAT!A40 -> EBIT | B40: =B5-B17 -> 75581.168 | C40: =B40/B$7*100 -> 7.9980072 | D40: =D5-D17 -> 70127.935 | E40: =D40/D$7*100 -> 7.1815602 | F40: =F5-F17 -> 79620.192 | G40: =F40/F$7*100 -> 7.7653615 | I40: =(D40-B40)/B40*100 -> -7.215068 | J40: =(F40-D40)/D40*100 -> 13.535629 | K40: =RESULTAAT!C40-RESULTAAT!B40 -> -5453.2326 | L40: =RESULTAAT!D40-RESULTAAT!C40 -> 9492.2571
A41: =RESULTAAT!A41 -> EBITDA | B41: =B40+B29+B30 -> 117581.17 | C41: =B41/B$7*100 -> 12.442452 | D41: =D40+D29+D30 -> 112127.94 | E41: =D41/D$7*100 -> 11.482635 | F41: =F40+F29+F30 -> 121620.19 | G41: =F41/F$7*100 -> 11.861624 | I41: =(D41-B41)/B41*100 -> -4.6378453 | J41: =(F41-D41)/D41*100 -> 8.4655595 | K41: =RESULTAAT!C41-RESULTAAT!B41 -> -5453.2326 | L41: =RESULTAAT!D41-RESULTAAT!C41 -> 9492.2571
A42: =RESULTAAT!A42 -> BEDRIJFSRESULTAAT | B42: =B5-B17 -> 75581.168 | C42: =B42/B$7*100 -> 7.9980072 | D42: =D5-D17 -> 70127.935 | E42: =D42/D$7*100 -> 7.1815602 | F42: =F5-F17 -> 79620.192 | G42: =F42/F$7*100 -> 7.7653615 | I42: =(D42-B42)/B42*100 -> -7.215068 | J42: =(F42-D42)/D42*100 -> 13.535629 | K42: =RESULTAAT!C42-RESULTAAT!B42 -> -5453.2326 | L42: =RESULTAAT!D42-RESULTAAT!C42 -> 9492.2571
A44: =RESULTAAT!A44 -> Financiële Opbrengsten | B44: =RESULTAAT!B44 -> 0 | C44: =B44/B$7*100 -> 0 | D44: =RESULTAAT!C44 -> 0 | E44: =D44/D$7*100 -> 0 | F44: =RESULTAAT!D44 -> 0 | G44: =F44/F$7*100 -> 0 | I44: =(D44-B44)/B44*100 -> #DIV/0! | J44: =(F44-D44)/D44*100 -> #DIV/0! | K44: =RESULTAAT!C44-RESULTAAT!B44 -> 0 | L44: =RESULTAAT!D44-RESULTAAT!C44 -> 0
A45: =RESULTAAT!A45 -> Financiële Kosten | B45: =RESULTAAT!B45 -> 12981.469 | C45: =B45/B$7*100 -> 1.3737005 | D45: =RESULTAAT!C45 -> 11925.827 | E45: =D45/D$7*100 -> 1.2212829 | F45: =RESULTAAT!D45 -> 10777.785 | G45: =F45/F$7*100 -> 1.0511579 | I45: =(D45-B45)/B45*100 -> -8.1319143 | J45: =(F45-D45)/D45*100 -> -9.6265209 | K45: =RESULTAAT!C45-RESULTAAT!B45 -> -1055.642 | L45: =RESULTAAT!D45-RESULTAAT!C45 -> -1148.0423
A46: =RESULTAAT!A46 -> Niet recurrent Financieel (+/-) | B46: =RESULTAAT!B46 -> 0 | C46: =B46/B$7*100 -> 0 | D46: =RESULTAAT!C46 -> 0 | E46: =D46/D$7*100 -> 0 | F46: =RESULTAAT!D46 -> 0 | G46: =F46/F$7*100 -> 0 | I46: =(D46-B46)/B46*100 -> #DIV/0! | J46: =(F46-D46)/D46*100 -> #DIV/0! | K46: =RESULTAAT!C46-RESULTAAT!B46 -> 0 | L46: =RESULTAAT!D46-RESULTAAT!C46 -> 0
A48: =RESULTAAT!A48 -> RESULTAAT VOOR BELASTING | B48: =B42+B44-B45 -> 62599.699 | C48: =B48/B$7*100 -> 6.6243067 | D48: =D42+D44-D45 -> 58202.108 | E48: =D48/D7*100 -> 5.9602773 | F48: =F42+F44-F45 -> 68842.407 | G48: =F48/F7*100 -> 6.7142035 | I48: =(D48-B48)/B48*100 -> -7.024939 | J48: =(F48-D48)/D48*100 -> 18.281639 | K48: =RESULTAAT!C48-RESULTAAT!B48 -> -4397.5907 | L48: =RESULTAAT!D48-RESULTAAT!C48 -> 10640.299
A50: =RESULTAAT!A50 -> Onttrekking aan de uitgestelde belasting | B50: =RESULTAAT!B50 -> 0 | D50: =RESULTAAT!C50 -> 0 | F50: =RESULTAAT!D50 -> 0 | I50: =(D50-B50)/B50*100 -> #DIV/0! | J50: =(F50-D50)/D50*100 -> #DIV/0! | K50: =RESULTAAT!C50-RESULTAAT!B50 -> 0 | L50: =RESULTAAT!D50-RESULTAAT!C50 -> 0
A51: =RESULTAAT!A51 -> Overboeking naar de uitgestelde belasting | B51: =RESULTAAT!B51 -> 0 | D51: =RESULTAAT!C51 -> 0 | F51: =RESULTAAT!D51 -> 0 | I51: =(D51-B51)/B51*100 -> #DIV/0! | J51: =(F51-D51)/D51*100 -> #DIV/0! | K51: =RESULTAAT!C51-RESULTAAT!B51 -> 0 | L51: =RESULTAAT!D51-RESULTAAT!C51 -> 0
A52: =RESULTAAT!A52 -> Belastingen op het resultaat | B52: =RESULTAAT!B52 -> 15649.925 | C52: =B52/B$7*100 -> 1.6560767 | D52: =RESULTAAT!C52 -> 14550.527 | E52: =D52/D7*100 -> 1.4900693 | F52: =RESULTAAT!D52 -> 17210.602 | G52: =F52/F7*100 -> 1.6785509 | I52: =(D52-B52)/B52*100 -> -7.024939 | J52: =(F52-D52)/D52*100 -> 18.281639 | K52: =RESULTAAT!C52-RESULTAAT!B52 -> -1099.3977 | L52: =RESULTAAT!D52-RESULTAAT!C52 -> 2660.0748
A54: =RESULTAAT!A54 -> NETTO RESULTAAT | B54: =B48+B50-B51-B52 -> 46949.774 | C54: =B54/B$7*100 -> 4.96823 | D54: =D48+D50-D51-D52 -> 43651.581 | E54: =D54/D7*100 -> 4.470208 | F54: =F48+F50-F51-F52 -> 51631.805 | G54: =F54/F7*100 -> 5.0356526 | I54: =(D54-B54)/B54*100 -> -7.024939 | J54: =(F54-D54)/D54*100 -> 18.281639 | K54: =RESULTAAT!C54-RESULTAAT!B54 -> -3298.193 | L54: =RESULTAAT!D54-RESULTAAT!C54 -> 7980.2245
A56: =RESULTAAT!A56 -> Onttrekking aan de Belastingvrije Reserves | B56: =RESULTAAT!B56 -> 0 | D56: =RESULTAAT!C56 -> 0 | F56: =RESULTAAT!D56 -> 0 | I56: =(D56-B56)/B56*100 -> #DIV/0! | J56: =(F56-D56)/D56*100 -> #DIV/0! | K56: =RESULTAAT!C56-RESULTAAT!B56 -> 0 | L56: =RESULTAAT!D56-RESULTAAT!C56 -> 0
...

Sheet INVEST TABEL
A1: =ACTIVA!A1 -> VDO
